# 异常处理

我们在[第 1 章](01.html)中简要介绍了异常，*开始使用 Java 12* 。 在本章中，我们将更系统地对待这一主题。 Java 中有两种异常：检查和未经检查的异常。 将证明两者都将说明，两者之间的差异将被解释。 读者还将了解与例外处理相关的 Java 构造的语法以及用于解决例外的最佳实践（处理）。 章节将结束 aserertion 语句的相关主题，可用于调试生产中的代码。

本章将介绍以下主题：

*   Java 例外框架
*   检查和未选中（运行时）异常
*   `try`，`catch`和`finally`块
*   `throws`声明
*   `throw`声明
*   `assert`声明
*   例外处理的最佳实践

# Java 例外框架

正如我们在[第 1 章](01.html)，*中所描述的 Java 12* 中所描述的，意外情况会导致 **Java 虚拟机**（ **JVM** ） 要创建并抛出异常对象，或者应用程序代码可以执行此操作。 一旦发生这种情况，如果在`try`块内抛出异常，则控制流程被传送到`catch`子句。 让我们看一个例子。 考虑以下方法：

```
void method(String s){
    if(s.equals("abc")){
        System.out.println("Equals abc");
    } else {
        System.out.println("Not equal");
    }
}
```

如果输入参数值为`null`，则可以期望将输出视为`Not equal`。 不幸的是，事实并非如此。 `s.equals("abc")`表达式在`s`变量引用的对象上调用`equals()`方法，但是，如果`s`变量是`null`，它不会引用任何对象。 让我们看看会发生什么。

让我们运行以下代码：

```
try {
    method(null);
} catch (Exception ex){
    System.out.println(ex.getClass().getCanonicalName());  
                              //prints: java.lang.NullPointerException
    ex.printStackTrace();     //prints: see the screenshot
    if(ex instanceof NullPointerException){
        //do something
    } else {
        //do something else
    }
}
```

此代码的输出如下：

![](img/823979db-4f8b-4c79-b453-77b17989e501.png)

在屏幕截图上以红色所看到的称为**堆栈跟踪**。 该名称来自 Method 调用的方式（作为堆栈）在 JVM 内存中：一个方法调用另一个方法，反过来拨打另一个，依此类推。 在最内部方法返回之后，堆栈返回，返回的方法（**堆栈帧**）从堆栈中删除（我们将更多地讨论[第 9 章](09.html)中的 JVM 内存结构。 ， *JVM 结构和垃圾收集*）。 当发生异常时，所有堆栈内容（堆栈帧）都返回为堆栈跟踪。 它允许我们追踪导致问题的代码行。

在我们的前述代码示例中，根据异常的类型执行不同的代码块。 在我们的情况下，它是`java.lang.NullPointerException`。 如果应用程序代码未捕获它，则此异常将通过被叫方法的堆栈传播到 JVM 中的堆栈，然后停止执行该应用程序。 为了避免这种情况，可以捕获异常，并且执行一些代码以从特殊条件恢复。

Java 中的异常处理框架的目的是保护应用程序代码免受意想不到的条件，如果可能的话从中恢复。 在以下部分中，我们将使用框架功能更详细地解剖其并重新编写给定示例。

# 检查和未经检查的异常

如果查找`java.lang`包 API 的文档，您将发现该软件包包含几乎三十个异常类和几十个错误类。 这两个组都扩展了`java.lang.Throwable`类，从中继承了所有方法，也不会添加其他方法。 `java.lang.Throwable`类的最常使用方法如下：

*   `void printStackTrace()`：输出方法调用的堆栈跟踪（堆栈帧）
*   `StackTraceElement[] getStackTrace()`：将与`printStackTrace()`返回相同的信息，但允许堆栈跟踪的任何帧的编程访问
*   `String getMessage()`：检索通常包含用户友好的解释的消息，原因是例外或错误
*   `Throwable getCause()`：检索`java.lang.Throwable`的可选对象，这是例外的原因（但代码的作者决定将其包裹在另一个例外或错误中）

所有错误都扩展了`java.lang.Error`类，又扩展了`java.lang.Throwable`类。 通常由 JVM 抛出错误，并且根据官方文档，*表示合理应用程序不应该尝试捕获*的严重问题。 这里有一些例子：

*   `OutOfMemoryError`：抛出 JVM 运行内存时抛出，无法使用垃圾收集清除它
*   `StackOverflowError`：当为方法调用的堆栈分配的内存时，抛出了不足以存储另一堆栈帧
*   `NoClassDefFoundError`：当 JVM 无法找到当前加载类所请求的类的定义时抛出

该框架的作者假设应用程序无法自动从这些错误中恢复，这被证明是一个很大程度上是正确的假设。 这就是为什么程序员通常不会捕获错误，我们不会再谈论它们了。

另一方面，异常通常与特定于应用程序特定问题有关，并且通常不要求我们关闭应用程序并允许恢复。 这就是为什么程序员通常捕获它们并实现应用程序逻辑的替代（到主流）路径，或者至少在不关闭应用程序的情况下报告问题。 这里有一些例子：

*   `ArrayIndexOutOfBoundsException`：代码尝试通过等于或大于数组长度的索引访问元素的抛出（请记住阵列的第一个元素具有索引`0`，因此索引等于外部的数组长度点 阵列）
*   `ClassCastException`：代码投入引用对类的参考或与变量引用的对象相关联的接口
*   `NumberFormatException`：抛出代码尝试将字符串转换为数字类型，但字符串不包含必要的数字格式

所有例外都扩展了`java.lang.Exception`类，又扩展了`java.lang.Throwable`类。 这就是为什么通过捕获`java.lang.Exception`类的对象，代码捕获任何异常类型的对象。 我们在这种方式捕获`java.lang.NullPointerException`，我们在 *java 例外框架*部分中展示了它。

其中一个例外是`java.lang.RuntimeException`。 扩展它的例外称为**运行时异常**或**未选中的异常**。 我们已经提到了其中一些：`NullPointerException`，`ArrayIndexOutOfBoundsException`，`ClassCastException`和`NumberFormatException`。 为什么他们被称为运行时异常很清楚，而为什么他们被称为未经检查的例外情况将在下一段中清楚。

他们在祖先中没有`java.lang.RuntimeException`的那些被称为**检查异常**。 此类名称的原因是编译器确保（检查）这些异常在方法的`throws`子句中被捕获或列出（请参阅 *threats 语句*部分）。 这种设计强制编程器进行有意识的决定，要么捕获检查的异常，要么通知客户端可以通过客户端抛出此异常的方法，并且必须由客户端处理（处理）。 以下是几个检查的例外情况：

*   `ClassNotFoundException`：在尝试使用其字符串名称使用`forName()`的`forName()`的方法加载类时，抛出了`forName()`失败
*   `CloneNotSupportedException`：当代码试图克隆一个不实现`Cloneable`接口的对象时抛出
*   `NoSuchMethodException`：当代码没有调用方法时抛出

并非所有异常都驻留在`java.lang`包中。 许多其他包包含与包支持的功能相关的异常。 例如，存在`java.util.MissingResourceException`运行时异常和`java.io.IOException`检查异常。

尽管没有被迫，程序员经常捕获运行时（未经检查）的异常，以便更好地控制程序流程，使应用程序的行为更稳定和可预测。 顺便说一下，所有错误也是运行时（未选中的）例外，但是，正如我们已经说过的那样，通常无法以编程方式处理它们，因此捕捉`java.lang.Error`类的后代没有点。

# 尝试，捕获，终于阻止

当在`try`块中抛出异常时，它将控制流重定向到第一个`catch`子句。 如果没有`catch`块可以捕获异常（但是必须到位`finally`块），则异常传播所有的方式启动和退出该方法。 如果有多个`catch`子句，则编译器强制您排列它们以便在父异常之前列出子例外。 让我们来看看以下例子：

```
void someMethod(String s){
    try {
       method(s);
    } catch (NullPointerException ex){
       //do something
    } catch (Exception ex){
       //do something else
    }
}
```

在前面的示例中，具有`NullPointerException`的`catch`块被放置在具有`Exception`的块之前，因为`NullPointerException`延伸`RuntimeException`，其又延伸`Exception`。 我们甚至可以实现此示例，如下所示：

```
void someMethod(String s){
    try {
        method(s);
    } catch (NullPointerException ex){
        //do something
    } catch (RuntimeException ex){
        //do something else
    } catch (Exception ex){
        //do something different
    }
}
```

第一个`catch`条款仅捕获`NullPointerException`。 将延伸`RuntimeException`的其他例外将被第二个`catch`条款陷入困境。 其余的异常类型（所有检查的异常）将被最后一个`catch`块抓住。 请注意，这些`catch`条款中的任何一个都不会被任何错误捕获错误。 要捕获它们，应该为`Error`（在任何位置）或`Throwable`（在上一个例子中的最后一个`catch`子句之后）添加`catch`子句，但程序员通常不执行它并允许错误传播 一直进入 JVM。

对于每个异常类型具有`catch`块允许我们提供异常类型的处理处理。 但是，如果异常处理没有区别，则可以只有一个`catch`块与`Exception`基类捕获所有类型的例外：

```
void someMethod(String s){
    try {
        method(s);
    } catch (Exception ex){
        //do something
    }
}
```

如果没有条款都捕获异常，则会进一步抛出它，直到它在其中一个方法中的`try...catch`语句中，或者将所有方式传播出应用程序代码。 在这种情况下，JVM 终止了应用程序和退出。

添加`finally`块不会更改所描述的行为。 如果存在，则始终执行，无论是否生成异常。 A `finally`块通常用于释放资源：关闭数据库连接，文件和类似。 但是，如果资源实现`Closeable` interface，最好使用尝试资源语句，允许自动释放资源。 以下是如何使用 Java 7 完成：

```
try (Connection conn = DriverManager.getConnection("dburl", 
                                         "username", "password");
     ResultSet rs = conn.createStatement()
                        .executeQuery("select * from some_table")) {
    while (rs.next()) {
        //process the retrieved data
    }
} catch (SQLException ex) {
    //Do something
    //The exception was probably caused by incorrect SQL statement
}
```

此示例创建数据库连接，检索数据并处理它，然后关闭（调用`close()`方法）`conn`和`rs`对象。

Java 9 通过允许创建表示`try`块之外的对象，然后在 Try-utory 语句中使用它们如下，使用它们来增强试验 - 资源语句功能

```
void method(Connection conn, ResultSet rs) {
    try (conn; rs) {
        while (rs.next()) {
            //process the retrieved data
        }
    } catch (SQLException ex) {
        //Do something
        //The exception was probably caused by incorrect SQL statement
    }
}
```

前面的代码看起来很清晰，虽然在实践中，程序员更喜欢在同一上下文中创建和释放（关闭）资源。 如果这是您的偏好，请考虑使用`throws`语句与尝试与资源语句结合。

# 抛出陈述

使用尝试与资源语句的前一个示例可以用与在同一上下文中创建的资源对象重新编写如下：

```
Connection conn;
ResultSet rs;
try {
    conn = DriverManager.getConnection("dburl", "username", "password");
    rs = conn.createStatement().executeQuery("select * from some_table");
} catch (SQLException e) {
    e.printStackTrace();
    return;
}

try (conn; rs) {
    while (rs.next()) {
        //process the retrieved data
    }
} catch (SQLException ex) {
    //Do something
    //The exception was probably caused by incorrect SQL statement
}
```

我们必须处理`SQLException`，因为它是一个被检查的异常，`getConnection()`，`createStatement()`，`executeQuery()`和`next()`方法在其`throws`子句中声明。 这是一个例子：

```
Statement createStatement() throws SQLException;
```

这意味着该方法的作者警告了该方法的用户，它可能会抛出这样的异常，并迫使它们捕获异常或在其方法的`throws`子句中声明它。 在我们的前述示例中，我们选择捕获它并不得不使用两个`try...catch`陈述。 或者，我们也可以在`throws`条款中列出异常，因此，通过有效地推动对我们方法的用户的异常处理的负担来删除杂乱：

```
void throwsDemo() throws SQLException {
    Connection conn = DriverManager.getConnection("url","user","pass");
    ResultSet rs = conn.createStatement().executeQuery("select * ...");
    try (conn; rs) {
        while (rs.next()) {
            //process the retrieved data
        }
    } finally { }
}
```

我们摆脱了`catch`条款，但 Java 语法要求`catch`或`finally`块必须遵循`try`块，因此我们添加了一个空的`finally`块。

`throws`子句允许但不需要我们列出未经检查的异常。 添加未选中的异常不会强制该方法的用户来处理它们。

最后，如果该方法抛出几种不同的例外，则可以列出基本`Exception`异常类而不是列出所有类别。 这将使编译器快乐，但不被视为良好的做法，因为它隐藏了特定例外的细节，方法的用户可能需要。

请注意，编译器不会检查方法的正文中的代码是否可以抛出什么样的异常。 因此，可以列出`throws`子句中的任何例外，可能导致不必要的开销。 如果错误地，程序员在`throws`子句中包括从未实际抛出的`throws`子句中的检查异常，则该方法的用户可以为从未执行的`catch`块写入。

# 抛弃陈述

`throw`语句允许抛出程序员认为所需的任何例外。 人们甚至可以创造自己的例外。 要创建检查的异常，请扩展`java.lang.Exception`类：

```
class MyCheckedException extends Exception{
    public MyCheckedException(String message){
        super(message);
    }
    //add code you need to have here
}
```

此外，要创建未选中的异常，请扩展`java.lang.RunitmeException`类，如下所示：

```
class MyUncheckedException extends RuntimeException{
    public MyUncheckedException(String message){
        super(message);
    }
    //add code you need to have here
}
```

注意评论*添加代码您需要在此处*。 您可以将方法和属性添加到自定义例外到任何其他常规类，但程序员很少做到这一点。 最佳实践甚至明确建议避免使用例外避免驾驶业务逻辑。 例外应该是名称所暗示的，仅涵盖卓越，非常罕见的情况。

但是，如果您需要宣布卓越条件，请使用`throw`关键字和`new`运算符创建和触发异常对象的传播。 这里有一些例子：

```
throw new Exception("Something happend"); 
throw new RunitmeException("Something happened");
throw new MyCheckedException("Something happened");
throw new MyUncheckedException("Something happened");
```

甚至可能抛出`null`如下：

```
throw null;
```

前面的声明结果与此结果相同：

```
throw new NullPointerException;
```

在这两种情况下，未选中的`NullPointerException`的对象开始通过系统传播，直到它被应用程序或 JVM 捕获。

# 断言声明

偶尔一次，程序员需要知道代码中是否发生了特定条件，即使在应用程序已经部署到生产后，即使在应用程序中也是如此。 与此同时，无需一直运行检查。 这就是分支`assert`陈述的派上方便的地方。 这是一个例子：

```
public someMethod(String s){
    //any code goes here
    assert(assertSomething(x, y, z));
    //any code goes here
}

boolean assertSomething(int x, String y, double z){
 //do something and return boolean
}
```

在前面的代码中，`assert()`方法从`assertSomething()`方法中输入。 如果`assertSomething()`方法返回`false`，则程序停止执行。

仅在使用`-ea`选项运行 JVM 时才会执行`assert()`方法。 不应在生产中使用`-ea`标志，除了可能暂时用于测试目的，因为它会产生影响应用程序性能的开销。

# 例外处理的最佳实践

检查的例外被设计用于可恢复的条件，当应用程序可以自动执行以修改或解决问题时。 在实践中，它不会经常发生。 通常，当捕获异常时，应用程序会记录堆栈跟踪并中止当前操作。 基于记录信息，应用程序支持团队修改代码以解决未来的情况或防止其在将来发生。

每个应用程序都不同，因此最好的实践取决于特定的应用程序要求，设计和上下文。 通常，似乎在开发社区中存在协议，以避免使用检查的异常，并最大限度地减少应用程序代码中的传播。 以下是一些其他建议证明是有用的：

*   始终捕获靠近源的所有检查异常
*   如有疑问，捕获未选中的异常，靠近源
*   处理尽可能靠近源的异常，因为它是上下文是最具体的，根本原因所在的位置
*   除非您需要，否则不要抛出检查的异常，因为您强制为可能永远发生的情况构建额外的代码
*   通过将其作为`RuntimeException`重新将其作为`RuntimeException`重新将其作为`RuntimeException`重新抛出，将第三方检查的异常转换为未选中
*   除非您需要，否则不要创建自定义异常
*   除非您必须使用异常处理机制，否则不要驱动业务逻辑
*   通过使用消息系统以及可选的枚举类型而不是使用异常类型来自定义通用`RuntimeException`，以便传达错误原因

# 概括

在本章中，读者介绍了 Java 异常处理框架，了解了两种异常 - 检查和未选中（运行时） - 以及如何使用`try-catch-finally`和`throws`语句处理它们。 读者还学习了如何生成（抛出）例外以及如何创建自己的（自定义）例外。 该章节结束了例外处理的最佳实践。

在下一章中，我们将详细讨论字符串及其处理，以及输入/输出流和文件读写技术。

# 测验

1.  什么是堆栈痕迹？ 选择所有应用：

    1.  目前加载的类列表
    2.  目前正在执行的方法列表
    3.  当前正在执行的代码行列表
    4.  目前使用的变量列表

2.  有什么例外的例外？ 选择所有符合条件的：
    1.  汇编例外
    2.  运行时异常
    3.  阅读例外
    4.  写例外

3.  以下代码的输出是多少？

```
try {
    throw null;
} catch (RuntimeException ex) {
    System.out.print("RuntimeException ");
} catch (Exception ex) {
    System.out.print("Exception ");
} catch (Error ex) {
    System.out.print("Error ");
} catch (Throwable ex) {
    System.out.print("Throwable ");
} finally {
    System.out.println("Finally ");
}
```

4.  以下哪种方法将编译在没有错误的情况下？

```
void method1() throws Exception { throw null; }
void method2() throws RuntimeException { throw null; }
void method3() throws Throwable { throw null; }
void method4() throws Error { throw null; }
```

5.  以下哪个陈述将没有错误编译？

```
throw new NullPointerException("Hi there!"); //1
throws new Exception("Hi there!");          //2
throw RuntimeException("Hi there!");       //3
throws RuntimeException("Hi there!");     //4
```

6.  假设`int x = 4`，以下哪个陈述将没有错误编译？

```
assert (x > 3); //1
assert (x = 3); //2
assert (x < 4); //3
assert (x = 4); //4
```

7.  以下列表中最佳实践是什么？
    1.  始终捕获所有例外和错误
    2.  总是抓住所有例外
    3.  永远不要扔掉未经检查的例外
    4.  除非你必须不要抛出检查的例外